Workbook

Sheet SalesData
A1: OrderID | B1: OrderDate | C1: Region | D1: Salesperson | E1: ProductID | F1: ProductName | G1: Category | H1: UnitPrice | I1: Quantity | J1: DiscountRate | K1: Revenue | L1: UnitCost | M1: Profit | N1: CustomerType | O1: Channel | P1: Returned | Q1: Notes
A2: ORD-0001 | B2: 46029 | C2: North | D2: Leo | E2: P002 | F2: DeskHub 8-in-1 | G2: Electronics | H2: 219 | I2: 8 | J2: 0 | K2: =H2*I2*(1-J2) -> 1752 | L2: 121 | M2: =K2-L2*I2 -> 784 | N2: Enterprise | O2: Online | P2: No
A3: ORD-0002 | B3: 46031 | C3: East | D3: Alice | E3: P007 | F3: CableKit Max | G3: Accessories | H3: 79 | I3: 7 | J3: 0 | K3: =H3*I3*(1-J3) -> 553 | L3: 28 | M3: =K3-L3*I3 -> 357 | N3: New | O3: Distributor | P3: No | Q3: Priority customer
A4: ORD-0003 | B4: 46079 | C4: West | D4: Ryan | E4: P007 | F4: CableKit Max | G4: Accessories | H4: 79 | I4: 1 | J4: 0 | K4: =H4*I4*(1-J4) -> 79 | L4: 28 | M4: =K4-L4*I4 -> 51 | N4: New | O4: Online | P4: No
A5: ORD-0004 | B5: 46049 | C5: East | D5: Kevin | E5: P006 | F5: TravelDock Lite | G5: Electronics | H5: 129 | I5: 4 | J5: 0.05 | K5: =H5*I5*(1-J5) -> 490.2 | L5: 67 | M5: =K5-L5*I5 -> 222.2 | N5: New | O5: Distributor | P5: No
A6: ORD-0005 | B6: 46160 | C6: East | D6: Kevin | E6: P008 | F6: MonitorArm X | G6: Office | H6: 269 | I6: 3 | J6: 0.1 | K6: =H6*I6*(1-J6) -> 726.3 | L6: 145 | M6: =K6-L6*I6 -> 291.3 | N6: Existing | O6: Distributor | P6: No
A7: ORD-0006 | B7: 46203 | C7: East | D7: Alice | E7: P004 | F7: CloudKeyboard Mini | G7: Electronics | H7: 399 | I7: 8 | J7: 0.05 | K7: =H7*I7*(1-J7) -> 3032.4 | L7: 230 | M7: =K7-L7*I7 -> 1192.4 | N7: New | O7: Direct Sales | P7: No
A8: ORD-0007 | B8: 46139 | C8: North | D8: Leo | E8: P005 | F8: FocusLamp | G8: Office | H8: 189 | I8: 12 | J8: 0.05 | K8: =H8*I8*(1-J8) -> 2154.6 | L8: 91 | M8: =K8-L8*I8 -> 1062.6 | N8: Enterprise | O8: Distributor | P8: No
A9: ORD-0008 | B9: 46178 | C9: South | D9: Mia | E9: P002 | F9: DeskHub 8-in-1 | G9: Electronics | H9: 219 | I9: 6 | J9: 0.08 | K9: =H9*I9*(1-J9) -> 1208.88 | L9: 121 | M9: =K9-L9*I9 -> 482.88 | N9: Enterprise | O9: Distributor | P9: No
A10: ORD-0009 | B10: 46198 | C10: North | D10: Leo | E10: P004 | F10: CloudKeyboard Mini | G10: Electronics | H10: 399 | I10: 8 | J10: 0 | K10: =H10*I10*(1-J10) -> 3192 | L10: 230 | M10: =K10-L10*I10 -> 1352 | N10: New | O10: Online | P10: No
A11: ORD-0010 | B11: 46077 | C11: West | D11: Ryan | E11: P006 | F11: TravelDock Lite | G11: Electronics | H11: 129 | I11: 15 | J11: 0 | K11: =H11*I11*(1-J11) -> 1935 | L11: 67 | M11: =K11-L11*I11 -> 930 | N11: Enterprise | O11: Distributor | P11: No
A12: ORD-0011 | B12: 46172 | C12: West | D12: Ryan | E12: P005 | F12: FocusLamp | G12: Office | H12: 189 | I12: 12 | J12: 0 | K12: =H12*I12*(1-J12) -> 2268 | L12: 91 | M12: =K12-L12*I12 -> 1176 | N12: Existing | O12: Online | P12: No
A13: ORD-0012 | B13: 46051 | C13: South | D13: Mia | E13: P001 | F13: AirMouse Pro | G13: Electronics | H13: 299 | I13: 14 | J13: 0.1 | K13: =H13*I13*(1-J13) -> 3767.4 | L13: 168 | M13: =K13-L13*I13 -> 1415.4 | N13: Enterprise | O13: Direct Sales | P13: Yes | Q13: Customer changed mind
A14: ORD-0013 | B14: 46164 | C14: East | D14: Alice | E14: P005 | F14: FocusLamp | G14: Office | H14: 189 | I14: 18 | J14: 0.05 | K14: =H14*I14*(1-J14) -> 3231.9 | L14: 91 | M14: =K14-L14*I14 -> 1593.9 | N14: Existing | O14: Direct Sales | P14: No
A15: ORD-0014 | B15: 46139 | C15: East | D15: Kevin | E15: P003 | F15: ErgoStand S2 | G15: Office | H15: 159 | I15: 17 | J15: 0 | K15: =H15*I15*(1-J15) -> 2703 | L15: 78 | M15: =K15-L15*I15 -> 1377 | N15: Enterprise | O15: Direct Sales | P15: No
A16: ORD-0015 | B16: 46062 | C16: North | D16: Leo | E16: P004 | F16: CloudKeyboard Mini | G16: Electronics | H16: 399 | I16: 18 | J16: 0.1 | K16: =H16*I16*(1-J16) -> 6463.8 | L16: 230 | M16: =K16-L16*I16 -> 2323.8 | N16: Existing | O16: Online | P16: No
A17: ORD-0016 | B17: 46115 | C17: North | D17: Leo | E17: P002 | F17: DeskHub 8-in-1 | G17: Electronics | H17: 219 | I17: 2 | J17: 0 | K17: =H17*I17*(1-J17) -> 438 | L17: 121 | M17: =K17-L17*I17 -> 196 | N17: New | O17: Distributor | P17: No
A18: ORD-0017 | B18: 46040 | C18: South | D18: Mia | E18: P008 | F18: MonitorArm X | G18: Office | H18: 269 | I18: 16 | J18: 0.1 | K18: =H18*I18*(1-J18) -> 3873.6 | L18: 145 | M18: =K18-L18*I18 -> 1553.6 | N18: Enterprise | O18: Direct Sales | P18: No
A19: ORD-0018 | B19: 46161 | C19: South | D19: Jason | E19: P004 | F19: CloudKeyboard Mini | G19: Electronics | H19: 399 | I19: 13 | J19: 0.15 | K19: =H19*I19*(1-J19) -> 4408.95 | L19: 230 | M19: =K19-L19*I19 -> 1418.95 | N19: Enterprise | O19: Direct Sales | P19: No
A20: ORD-0019 | B20: 46086 | C20: South | D20: Mia | E20: P002 | F20: DeskHub 8-in-1 | G20: Electronics | H20: 219 | I20: 11 | J20: 0 | K20: =H20*I20*(1-J20) -> 2409 | L20: 121 | M20: =K20-L20*I20 -> 1078 | N20: New | O20: Online | P20: No
A21: ORD-0020 | B21: 46184 | C21: East | D21: Alice | E21: P002 | F21: DeskHub 8-in-1 | G21: Electronics | H21: 219 | I21: 3 | J21: 0 | K21: =H21*I21*(1-J21) -> 657 | L21: 121 | M21: =K21-L21*I21 -> 294 | N21: New | O21: Direct Sales | P21: No
A22: ORD-0021 | B22: 46077 | C22: South | D22: Jason | E22: P008 | F22: MonitorArm X | G22: Office | H22: 269 | I22: 8 | J22: 0.08 | K22: =H22*I22*(1-J22) -> 1979.84 | L22: 145 | M22: =K22-L22*I22 -> 819.84 | N22: New | O22: Distributor | P22: No
A23: ORD-0022 | B23: 46113 | C23: West | D23: Ryan | E23: P007 | F23: CableKit Max | G23: Accessories | H23: 79 | I23: 15 | J23: 0.15 | K23: =H23*I23*(1-J23) -> 1007.25 | L23: 28 | M23: =K23-L23*I23 -> 587.25 | N23: Enterprise | O23: Online | P23: Yes | Q23: Wrong model ordered
A24: ORD-0023 | B24: 46126 | C24: North | D24: Leo | E24: P001 | F24: AirMouse Pro | G24: Electronics | H24: 299 | I24: 8 | J24: 0 | K24: =H24*I24*(1-J24) -> 2392 | L24: 168 | M24: =K24-L24*I24 -> 1048 | N24: Existing | O24: Online | P24: No
A25: ORD-0024 | B25: 46141 | C25: South | D25: Mia | E25: P005 | F25: FocusLamp | G25: Office | H25: 189 | I25: 15 | J25: 0.1 | K25: =H25*I25*(1-J25) -> 2551.5 | L25: 91 | M25: =K25-L25*I25 -> 1186.5 | N25: Enterprise | O25: Online | P25: No
A26: ORD-0025 | B26: 46083 | C26: South | D26: Jason | E26: P002 | F26: DeskHub 8-in-1 | G26: Electronics | H26: 219 | I26: 16 | J26: 0.08 | K26: =H26*I26*(1-J26) -> 3223.68 | L26: 121 | M26: =K26-L26*I26 -> 1287.68 | N26: New | O26: Online | P26: No
A27: ORD-0026 | B27: 46023 | C27: West | D27: Ryan | E27: P007 | F27: CableKit Max | G27: Accessories | H27: 79 | I27: 15 | J27: 0.05 | K27: =H27*I27*(1-J27) -> 1125.75 | L27: 28 | M27: =K27-L27*I27 -> 705.75 | N27: Enterprise | O27: Distributor | P27: No
A28: ORD-0027 | B28: 46062 | C28: South | D28: Jason | E28: P008 | F28: MonitorArm X | G28: Office | H28: 269 | I28: 7 | J28: 0 | K28: =H28*I28*(1-J28) -> 1883 | L28: 145 | M28: =K28-L28*I28 -> 868 | N28: Enterprise | O28: Direct Sales | P28: No
A29: ORD-0028 | B29: 46035 | C29: West | D29: Nina | E29: P001 | F29: AirMouse Pro | G29: Electronics | H29: 299 | I29: 2 | J29: 0.1 | K29: =H29*I29*(1-J29) -> 538.2 | L29: 168 | M29: =K29-L29*I29 -> 202.2 | N29: Enterprise | O29: Online | P29: No
A30: ORD-0029 | B30: 46126 | C30: East | D30: Alice | E30: P004 | F30: CloudKeyboard Mini | G30: Electronics | H30: 399 | I30: 2 | J30: 0.1 | K30: =H30*I30*(1-J30) -> 718.2 | L30: 230 | M30: =K30-L30*I30 -> 258.2 | N30: Enterprise | O30: Distributor | P30: No
A31: ORD-0030 | B31: 46089 | C31: South | D31: Jason | E31: P006 | F31: TravelDock Lite | G31: Electronics | H31: 129 | I31: 8 | J31: 0.05 | K31: =H31*I31*(1-J31) -> 980.4 | L31: 67 | M31: =K31-L31*I31 -> 444.4 | N31: Existing | O31: Direct Sales | P31: No
A32: ORD-0031 | B32: 46041 | C32: East | D32: Kevin | E32: P006 | F32: TravelDock Lite | G32: Electronics | H32: 129 | I32: 4 | J32: 0 | K32: =H32*I32*(1-J32) -> 516 | L32: 67 | M32: =K32-L32*I32 -> 248 | N32: New | O32: Direct Sales | P32: No
A33: ORD-0032 | B33: 46085 | C33: North | D33: Emma | E33: P002 | F33: DeskHub 8-in-1 | G33: Electronics | H33: 219 | I33: 6 | J33: 0.08 | K33: =H33*I33*(1-J33) -> 1208.88 | L33: 121 | M33: =K33-L33*I33 -> 482.88 | N33: Enterprise | O33: Distributor | P33: No
A34: ORD-0033 | B34: 46193 | C34: North | D34: Leo | E34: P001 | F34: AirMouse Pro | G34: Electronics | H34: 299 | I34: 5 | J34: 0.05 | K34: =H34*I34*(1-J34) -> 1420.25 | L34: 168 | M34: =K34-L34*I34 -> 580.25 | N34: Enterprise | O34: Online | P34: No
A35: ORD-0034 | B35: 46095 | C35: South | D35: Jason | E35: P005 | F35: FocusLamp | G35: Office | H35: 189 | I35: 7 | J35: 0.15 | K35: =H35*I35*(1-J35) -> 1124.55 | L35: 91 | M35: =K35-L35*I35 -> 487.55 | N35: Existing | O35: Direct Sales | P35: No
... A58: ORD-0057 | B58: 46170 | C58: West | D58: Ryan | E58: P001 | F58: AirMouse Pro | G58: Electronics | H58: 299 | I58: 1 | J58: 0.05 | K58: =H58*I58*(1-J58) -> 284.05 | L58: 168 | M58: =K58-L58*I58 -> 116.05 | N58: Existing | O58: Distributor | P58: No
A59: ORD-0058 | B59: 46147 | C59: South | D59: Jason | E59: P004 | F59: CloudKeyboard Mini | G59: Electronics | H59: 399 | I59: 14 | J59: 0.08 | K59: =H59*I59*(1-J59) -> 5139.12 | L59: 230 | M59: =K59-L59*I59 -> 1919.12 | N59: Enterprise | O59: Distributor | P59: Yes | Q59: Customer changed mind
A60: ORD-0059 | B60: 46065 | C60: West | D60: Nina | E60: P007 | F60: CableKit Max | G60: Accessories | H60: 79 | I60: 18 | J60: 0 | K60: =H60*I60*(1-J60) -> 1422 | L60: 28 | M60: =K60-L60*I60 -> 918 | N60: Enterprise | O60: Online | P60: No
A61: ORD-0060 | B61: 46187 | C61: West | D61: Nina | E61: P002 | F61: DeskHub 8-in-1 | G61: Electronics | H61: 219 | I61: 15 | J61: 0 | K61: =H61*I61*(1-J61) -> 3285 | L61: 121 | M61: =K61-L61*I61 -> 1470 | N61: Existing | O61: Online | P61: Yes | Q61: Customer changed mind
A62: ORD-0061 | B62: 46106 | C62: North | D62: Emma | E62: P008 | F62: MonitorArm X | G62: Office | H62: 269 | I62: 9 | J62: 0.08 | K62: =H62*I62*(1-J62) -> 2227.32 | L62: 145 | M62: =K62-L62*I62 -> 922.32 | N62: New | O62: Distributor | P62: No
...

Sheet Products
A1: ProductID | B1: ProductName | C1: Category | D1: ListPrice | E1: UnitCost
A2: P001 | B2: AirMouse Pro | C2: Electronics | D2: 299 | E2: 168
A3: P002 | B3: DeskHub 8-in-1 | C3: Electronics | D3: 219 | E3: 121
A4: P003 | B4: ErgoStand S2 | C4: Office | D4: 159 | E4: 78
A5: P004 | B5: CloudKeyboard Mini | C5: Electronics | D5: 399 | E5: 230
A6: P005 | B6: FocusLamp | C6: Office | D6: 189 | E6: 91
A7: P006 | B7: TravelDock Lite | C7: Electronics | D7: 129 | E7: 67
A8: P007 | B8: CableKit Max | C8: Accessories | D8: 79 | E8: 28
A9: P008 | B9: MonitorArm X | C9: Office | D9: 269 | E9: 145

Sheet MonthlySummary
A1: Month | B1: Revenue | C1: Profit | D1: Orders | E1: Avg Order Value | F1: Returned Orders
A2: 46023 | B2: =SUMIFS(SalesData!$K$2:$K$121,SalesData!$B$2:$B$121,">="&A2,SalesData!$B$2:$B$121,"<"&A3) -> 25674.34 | C2: =SUMIFS(SalesData!$M$2:$M$121,SalesData!$B$2:$B$121,">="&A2,SalesData!$B$2:$B$121,"<"&A3) -> 11199.34 | D2: =COUNTIFS(SalesData!$B$2:$B$121,">="&A2,SalesData!$B$2:$B$121,"<"&A3) -> 17 | E2: =IF(D2=0,0,B2/D2) -> 1510.2553 | F2: =COUNTIFS(SalesData!$B$2:$B$121,">="&A2,SalesData!$B$2:$B$121,"<"&A3,SalesData!$P$2:$P$121,"Yes") -> 1
A3: 46054 | B3: =SUMIFS(SalesData!$K$2:$K$121,SalesData!$B$2:$B$121,">="&A3,SalesData!$B$2:$B$121,"<"&A4) -> 38158.58 | C3: =SUMIFS(SalesData!$M$2:$M$121,SalesData!$B$2:$B$121,">="&A3,SalesData!$B$2:$B$121,"<"&A4) -> 16381.58 | D3: =COUNTIFS(SalesData!$B$2:$B$121,">="&A3,SalesData!$B$2:$B$121,"<"&A4) -> 16 | E3: =IF(D3=0,0,B3/D3) -> 2384.9112 | F3: =COUNTIFS(SalesData!$B$2:$B$121,">="&A3,SalesData!$B$2:$B$121,"<"&A4,SalesData!$P$2:$P$121,"Yes") -> 1
A4: 46082 | B4: =SUMIFS(SalesData!$K$2:$K$121,SalesData!$B$2:$B$121,">="&A4,SalesData!$B$2:$B$121,"<"&A5) -> 47245.48 | C4: =SUMIFS(SalesData!$M$2:$M$121,SalesData!$B$2:$B$121,">="&A4,SalesData!$B$2:$B$121,"<"&A5) -> 19579.48 | D4: =COUNTIFS(SalesData!$B$2:$B$121,">="&A4,SalesData!$B$2:$B$121,"<"&A5) -> 22 | E4: =IF(D4=0,0,B4/D4) -> 2147.5218 | F4: =COUNTIFS(SalesData!$B$2:$B$121,">="&A4,SalesData!$B$2:$B$121,"<"&A5,SalesData!$P$2:$P$121,"Yes") -> 0
A5: 46113 | B5: =SUMIFS(SalesData!$K$2:$K$121,SalesData!$B$2:$B$121,">="&A5,SalesData!$B$2:$B$121,"<"&A6) -> 36715.24 | C5: =SUMIFS(SalesData!$M$2:$M$121,SalesData!$B$2:$B$121,">="&A5,SalesData!$B$2:$B$121,"<"&A6) -> 16572.24 | D5: =COUNTIFS(SalesData!$B$2:$B$121,">="&A5,SalesData!$B$2:$B$121,"<"&A6) -> 21 | E5: =IF(D5=0,0,B5/D5) -> 1748.3448 | F5: =COUNTIFS(SalesData!$B$2:$B$121,">="&A5,SalesData!$B$2:$B$121,"<"&A6,SalesData!$P$2:$P$121,"Yes") -> 1
A6: 46143 | B6: =SUMIFS(SalesData!$K$2:$K$121,SalesData!$B$2:$B$121,">="&A6,SalesData!$B$2:$B$121,"<"&A7) -> 51838.98 | C6: =SUMIFS(SalesData!$M$2:$M$121,SalesData!$B$2:$B$121,">="&A6,SalesData!$B$2:$B$121,"<"&A7) -> 21174.98 | D6: =COUNTIFS(SalesData!$B$2:$B$121,">="&A6,SalesData!$B$2:$B$121,"<"&A7) -> 21 | E6: =IF(D6=0,0,B6/D6) -> 2468.5229 | F6: =COUNTIFS(SalesData!$B$2:$B$121,">="&A6,SalesData!$B$2:$B$121,"<"&A7,SalesData!$P$2:$P$121,"Yes") -> 2
A7: 46174 | B7: =SUMIFS(SalesData!$K$2:$K$121,SalesData!$B$2:$B$121,">="&A7,SalesData!$B$2:$B$121,"<"&DATE(2026,7,1)) -> 46031.15 | C7: =SUMIFS(SalesData!$M$2:$M$121,SalesData!$B$2:$B$121,">="&A7,SalesData!$B$2:$B$121,"<"&DATE(2026,7,1)) -> 20181.15 | D7: =COUNTIFS(SalesData!$B$2:$B$121,">="&A7,SalesData!$B$2:$B$121,"<"&DATE(2026,7,1)) -> 23 | E7: =IF(D7=0,0,B7/D7) -> 2001.3543 | F7: =COUNTIFS(SalesData!$B$2:$B$121,">="&A7,SalesData!$B$2:$B$121,"<"&DATE(2026,7,1),SalesData!$P$2:$P$121,"Yes") -> 3
A8: Total | B8: =SUM(B2:B7) -> 245663.77 | C8: =SUM(C2:C7) -> 105088.77 | D8: =SUM(D2:D7) -> 120 | E8: =IF(D8=0,0,B8/D8) -> 2047.1981 | F8: =SUM(F2:F7) -> 8
